Traceback (most recent call last):
  File "/Users/sstewart/anaconda3/lib/python3.7/site-packages/jupyter_cache/executors/utils.py", line 56, in single_nb_execution
    record_timing=False,
  File "/Users/sstewart/anaconda3/lib/python3.7/site-packages/nbclient/client.py", line 1082, in execute
    return NotebookClient(nb=nb, resources=resources, km=km, **kwargs).execute()
  File "/Users/sstewart/anaconda3/lib/python3.7/site-packages/nbclient/util.py", line 74, in wrapped
    return just_run(coro(*args, **kwargs))
  File "/Users/sstewart/anaconda3/lib/python3.7/site-packages/nbclient/util.py", line 53, in just_run
    return loop.run_until_complete(coro)
  File "/Users/sstewart/anaconda3/lib/python3.7/asyncio/base_events.py", line 587, in run_until_complete
    return future.result()
  File "/Users/sstewart/anaconda3/lib/python3.7/site-packages/nbclient/client.py", line 536, in async_execute
    cell, index, execution_count=self.code_cells_executed + 1
  File "/Users/sstewart/anaconda3/lib/python3.7/site-packages/nbclient/client.py", line 827, in async_execute_cell
    self._check_raise_for_error(cell, exec_reply)
  File "/Users/sstewart/anaconda3/lib/python3.7/site-packages/nbclient/client.py", line 735, in _check_raise_for_error
    raise CellExecutionError.from_cell_and_msg(cell, exec_reply['content'])
nbclient.exceptions.CellExecutionError: An error occurred while executing the following cell:
------------------
import requests

url = "https://github.com/ststewart/synestiabook2/tree/master/synestia-book/docs/syndef/"
fin = open('TE_Example03_Cool01_snapshot_10500_long', 'rb')
files = {'file': fin}
try:
    r = requests.post(url, files=files)


------------------

[0;36m  File [0;32m"<ipython-input-1-645546b2aa23>"[0;36m, line [0;32m8[0m
[0;31m    [0m
[0m    ^[0m
[0;31mSyntaxError[0m[0;31m:[0m unexpected EOF while parsing

SyntaxError: unexpected EOF while parsing (<ipython-input-1-645546b2aa23>, line 8)

